Ques - 1
------------
Given:
11. public static void parse(String str) {
12. try {
13. float f = Float.parseFloat(str);
14. } catch (NumberFormatException nfe) {
15. f = 0;
16. } finally {
17. System.out.println(f);
18. }
19. }
20. public static void main(String[] args) {
21. parse("invalid");
22. }
What is the result?
A. 0.0
B. Compilation fails.
C. A ParseException is thrown by the parse method at runtime.
D. A NumberFormatException is thrown by the parse method at runtime.

Ques - 2
-------------
Given:
11. public static void main(String[] args) {
12. try {
13. args = null;
14. args[0] = "test";
15. System.out.println(args[0]);
16. } catch (Exception ex) {
17. System.out.println("Exception");
18. } catch (NullPointerException npe) {
19. System.out.println("NullPointerException");
20. }
21. }

What is the result?
A. test
B. Exception
C. Compilation fails.
D. NullPointerException
Answer: 

Ques - 3
------------
Given:
11. static void test() throws RuntimeException {
12. try {
13. System.out.print("test ");
14. throw new RuntimeException();
15. }
16. catch (Exception ex) { System.out.print("exception "); }
17. }
18. public static void main(String[] args) {
19. try { test(); }
20. catch (RuntimeException ex) { System.out.print("runtime "); }
21. System.out.print("end ");
22. }
What is the result?
A. test end
B. Compilation fails.
C. test runtime end
D. test exception end
E. A Throwable is thrown by main at runtime.
Answer: 



Ques -4 
-----------
Given:
33. try {
34. // some code here
35. } catch (NullPointerException e1) {
36. System.out.print("a");
37. } catch (Exception e2) {
38. System.out.print("b");
39. } finally {
40. System.out.print("c");
41. }
If some sort of exception is thrown at line 34, which output is possible?
A. a
B. b
C. c
D. ac
E. abc
Answer: 

Ques - 5
---------------
Given:
31. // some code here
32. try {
33. // some code here
34. } catch (SomeException se) {
35. // some code here
36. } finally {
37. // some code here
38. }
Under which three circumstances will the code on line 37 be executed? (Choose three.)
A. The instance gets garbage collected.
B. The code on line 33 throws an exception.
C. The code on line 35 throws an exception.
D. The code on line 31 throws an exception.
E. The code on line 33 executes successfully.
Answer: 

Ques - 6
--------------
Given:
1. public class Boxer1{
2. Integer i;
3. int x;
4. public Boxer1(int y) {
5. x = i+y;
6. System.out.println(x);
7. }
8. public static void main(String[] args) {
9. new Boxer1(new Integer(4));
10. }
11. }
What is the result?
A. The value "4" is printed at the command line.
B. Compilation fails because of an error in line 5.
C. Compilation fails because of an error in line 9.
D. A NullPointerException occurs at runtime.
E. A NumberFormatException occurs at runtime.
F. An IllegalStateException occurs at runtime.
Answer: 

QUes - 7
--------------
Given:
11. static void test() {
12. try {
13. String x = null;
14. System.out.print(x.toString() + " ");
15. }
16. finally { System.out.print("finally "); }
17. }
18. public static void main(String[] args) {
19. try { test(); }
20. catch (Exception ex) { System.out.print("exception "); }
21. }
What is the result?
A. null
B. finally
C. null finally
D. Compilation fails.
E. finally exception
Answer: 

Ques - 8
--------------
Given:
1. class TestException extends Exception { }
2. class A {
3. public String sayHello(String name) throws TestException {
4. if(name == null) throw new TestException();
5. return "Hello " + name;
6. }
7. }
8. public class TestA {
9. public static void main(String[] args) {
10. new A().sayHello("Aiko");
11. }
12. }
Which statement is true?
A. Compilation succeeds.
B. Class A does not compile.
C. The method declared on line 9 cannot be modified to throw TestException.
D. TestA compiles if line 10 is enclosed in a try/catch block that catches TestException.
Answer: 

Ques - 9
-------------
Given:
10. public class Foo {
11. static int[] a;
12. static { a[0]=2; }
13. public static void main( String[] args ) {}
14. }
Which exception or error will be thrown when a programmer attempts to run this code?
A. java.lang.StackOverflowError
B. java.lang.IllegalStateException
C. java.lang.ExceptionInInitializerError
D. java.lang.ArrayIndexOutOfBoundsException

Answer: 

Ques - 10
----------------
Given:
5. class A {
6. void foo() throws Exception { throw new Exception(); }
7. }
8. class SubB2 extends A {
9. void foo() { System.out.println("B "); }
10. }
11. class Tester {
12. public static void main(String[] args) {
13. A a = new SubB2();
14. a.foo();
15. }
16. }
What is the result?
A. B
B. B, followed by an Exception.
C. Compilation fails due to an error on line 9.
D. Compilation fails due to an error on line 14.
E. An Exception is thrown with no other output.
Answer: 

Ques - 11
--------------
Given:
11. class X { public void foo() { System.out.print("X "); } }
12.
13. public class SubB extends X {
14. public void foo() throws RuntimeException {
15. super.foo();
16. if (true) throw new RuntimeException();
17. System.out.print("B ");
18. }
19. public static void main(String[] args) {
20. new SubB().foo();
21. }
22. }
What is the result?
A. X, followed by an Exception.
B. No output, and an Exception is thrown.
C. Compilation fails due to an error on line 14.
D. Compilation fails due to an error on line 16.
E. Compilation fails due to an error on line 17.
F. X, followed by an Exception, followed by B.
Answer: 


Ques - 12
---------------
Given:
5. class A {
6. void foo() throws Exception { throw new Exception(); }
7. }
8. class SubB2 extends A {
9. void foo() { System.out.println("B "); }
10. }
11. class Tester {
12. public static void main(String[] args) {
13. A a = new SubB2();
14. a.foo(); 15. }
16. }
What is the result?
A. B
B. B, followed by an Exception.
C. Compilation fails due to an error on line 9.
 D. Compilation fails due to an error on line 14.
E. An Exception is thrown with no other output
Answer: 

Ques - 13
---------------
Given:
11. static void test() {
12. try {
13. String x = null;
14. System.out.print(x.toString() + " ");
15. }
16. finally { System.out.print("finally "); }
17. }
18. public static void main(String[] args) {
19. try { test(); }
20. catch (Exception ex) { System.out.print("exception "); }
21. } What is the result?
A. null
B. finally
C. null finally
D. Compilation fails.
E. finally exception
Answer: 

Ques - 14
---------------
Given:
11. class A {
12. public void process() { System.out.print("A,"); }
13. class B extends A {
14. public void process() throws IOException {
15. super.process();
16. System.out.print("B,");
17. throw new IOException();
18. }
19. public static void main(String[] args) {
20. try { new B().process(); }
21. catch (IOException e) { System.out.println("Exception"); }
22. }
What is the result?
A. Exception
B. A,B,Exception
C. Compilation fails because of an error in line 20.
D. Compilation fails because of an error in line 14.
E. A NullPointerException is thrown at runtime.
Answer: 
Ques - 15
---------------
What is wrong with the following code?
public class MyClass {
 public static void main(String[] args) throws A {
 try {
 f();
 } finally {
 System.out.println("Done.");
 } catch (A e) {
 throw e;
 }
 }
 public static void f() throws B {
 throw new B();
 }
}
class A extends Throwable {}
class B extends A {}
Select the one correct answer.
(a) The main() method must declare that it throws B.
(b) The finally block must follow the catch block in the main() method.
(c) The catch block in the main() method must declare that it catches B rather
than A.
(d) A single try block cannot be followed by both a finally and a catch block.
(e) The declaration of class A is illegal.


Ques - 16
---------------
What, if anything, would cause the following code not to compile?
class A {
 void f() throws ArithmeticException {
 //...
 }
}
public class MyClass extends A {
 public static void main(String[] args) {
 A obj = new MyClass();
 try {
 obj.f();
 } catch (ArithmeticException e) {
 return;
 } catch (Exception e) {
 System.out.println(e);
 throw new RuntimeException("Something wrong here");
 }
 }
 // InterruptedException is a direct subclass of Exception.
 void f() throws InterruptedException {
 //...
 }
}
Select the one correct answer.
(a) The main() method must declare that it throws RuntimeException.
(b) The overriding f() method in MyClass must declare that it throws ArithmeticException, since the f() method in class A declares that it does.
(c) The overriding f() method in MyClass is not allowed to throw InterruptedException, since the f() method in class A does not throw this exception.
(d) The compiler will complain that the catch(ArithmeticException) block shadows the catch(Exception) block.
(e) You cannot throw exceptions from a catch block.
(f) Nothing is wrong with the code, it will compile without errors.


Ques - 17
---------------

class Super {
	public void m1() throws ArithmeticException { //1
		System.out.println("M1 from super..");
		throw new NullPointerException();//2
	}
}

class Sub extends Super {
	public void m1() throws ClassNotFoundException {//3
		System.out.println("M2 from sub..");
		throw new ArithmeticException();//4
	}
}

public class TestMCQ {
	public static void main(String[] args) {
		Super s = new Sub();
		s.m1();//5
	}

}


Which Line no will cause Compile time error
A. 1
B. 2
C. 3
D. 4
E. 5

Ans : 

Ques - 18
---------------
class Super {
	public void m1() { // 1
		System.out.println("M1 from super..");
		throw new NullPointerException();// 2
	}
}

class Sub extends Super {
	public void m1() throws ArithmeticException {// 4 {//3
		System.out.println("M2 from sub..");
		throw new ArithmeticException();// 4
	}
}

public class TestMCQ {
	public static void main(String[] args) {
		Super s = new Sub();
		try {
		s.m1();// 5
		}catch(ArithmeticException e) {
			System.out.println("Exception Caught ....");
		}
	}

}

Which Line no will cause Compile time error
A. 1
B. 2
C. 3
D. 4
E. 5
F. Compiles Fine

Ans :

Ques - 19
---------------
Ques - 20
---------------
